2019-09-10 15:50:31,610 - metegol - ERROR - MISCONF Redis is configured to save RDB snapshots, but it is currently not able to persist on disk. Commands that may modify the data set are disabled, because this instance is configured to report errors during writes if RDB snapshotting fails (stop-writes-on-bgsave-error option). Please check the Redis logs for details about the RDB error.
Traceback (most recent call last):
  File "/Users/juanpirossi/Documents/personal-projects/metegolBotTelegram/src/utils.py", line 30, in func_wrapper
    func(*args, **kwargs)
  File "/Users/juanpirossi/Documents/personal-projects/metegolBotTelegram/src/games.py", line 27, in submit
    uid = redis_set(json.dumps(data))
  File "/Users/juanpirossi/Documents/personal-projects/metegolBotTelegram/src/utils.py", line 15, in redis_set
    r.set(uid, value, ex=300)
  File "/usr/local/lib/python3.7/site-packages/redis/client.py", line 1519, in set
    return self.execute_command('SET', *pieces)
  File "/usr/local/lib/python3.7/site-packages/redis/client.py", line 839, in execute_command
    return self.parse_response(conn, command_name, **options)
  File "/usr/local/lib/python3.7/site-packages/redis/client.py", line 853, in parse_response
    response = connection.read_response()
  File "/usr/local/lib/python3.7/site-packages/redis/connection.py", line 717, in read_response
    raise response
redis.exceptions.ResponseError: MISCONF Redis is configured to save RDB snapshots, but it is currently not able to persist on disk. Commands that may modify the data set are disabled, because this instance is configured to report errors during writes if RDB snapshotting fails (stop-writes-on-bgsave-error option). Please check the Redis logs for details about the RDB error.
2019-09-10 15:50:31,610 - metegol - ERROR - MISCONF Redis is configured to save RDB snapshots, but it is currently not able to persist on disk. Commands that may modify the data set are disabled, because this instance is configured to report errors during writes if RDB snapshotting fails (stop-writes-on-bgsave-error option). Please check the Redis logs for details about the RDB error.
Traceback (most recent call last):
  File "/Users/juanpirossi/Documents/personal-projects/metegolBotTelegram/src/utils.py", line 30, in func_wrapper
    func(*args, **kwargs)
  File "/Users/juanpirossi/Documents/personal-projects/metegolBotTelegram/src/games.py", line 27, in submit
    uid = redis_set(json.dumps(data))
  File "/Users/juanpirossi/Documents/personal-projects/metegolBotTelegram/src/utils.py", line 15, in redis_set
    r.set(uid, value, ex=300)
  File "/usr/local/lib/python3.7/site-packages/redis/client.py", line 1519, in set
    return self.execute_command('SET', *pieces)
  File "/usr/local/lib/python3.7/site-packages/redis/client.py", line 839, in execute_command
    return self.parse_response(conn, command_name, **options)
  File "/usr/local/lib/python3.7/site-packages/redis/client.py", line 853, in parse_response
    response = connection.read_response()
  File "/usr/local/lib/python3.7/site-packages/redis/connection.py", line 717, in read_response
    raise response
redis.exceptions.ResponseError: MISCONF Redis is configured to save RDB snapshots, but it is currently not able to persist on disk. Commands that may modify the data set are disabled, because this instance is configured to report errors during writes if RDB snapshotting fails (stop-writes-on-bgsave-error option). Please check the Redis logs for details about the RDB error.
2019-09-10 15:52:59,704 - metegol - ERROR - can only concatenate str (not "int") to str
Traceback (most recent call last):
  File "/Users/juanpirossi/Documents/personal-projects/metegolBotTelegram/src/utils.py", line 30, in func_wrapper
    func(*args, **kwargs)
  File "/Users/juanpirossi/Documents/personal-projects/metegolBotTelegram/src/callbacks.py", line 22, in inline_button_callback
    _submit_score(bot, data, update.callback_query.message.chat_id)
  File "/Users/juanpirossi/Documents/personal-projects/metegolBotTelegram/src/games.py", line 162, in _submit_score
    ": " + data["opponent"]["points"]
TypeError: can only concatenate str (not "int") to str
2019-09-10 15:52:59,704 - metegol - ERROR - can only concatenate str (not "int") to str
Traceback (most recent call last):
  File "/Users/juanpirossi/Documents/personal-projects/metegolBotTelegram/src/utils.py", line 30, in func_wrapper
    func(*args, **kwargs)
  File "/Users/juanpirossi/Documents/personal-projects/metegolBotTelegram/src/callbacks.py", line 22, in inline_button_callback
    _submit_score(bot, data, update.callback_query.message.chat_id)
  File "/Users/juanpirossi/Documents/personal-projects/metegolBotTelegram/src/games.py", line 162, in _submit_score
    ": " + data["opponent"]["points"]
TypeError: can only concatenate str (not "int") to str
2019-09-10 15:52:59,704 - metegol - ERROR - can only concatenate str (not "int") to str
Traceback (most recent call last):
  File "/Users/juanpirossi/Documents/personal-projects/metegolBotTelegram/src/utils.py", line 30, in func_wrapper
    func(*args, **kwargs)
  File "/Users/juanpirossi/Documents/personal-projects/metegolBotTelegram/src/callbacks.py", line 22, in inline_button_callback
    _submit_score(bot, data, update.callback_query.message.chat_id)
  File "/Users/juanpirossi/Documents/personal-projects/metegolBotTelegram/src/games.py", line 162, in _submit_score
    ": " + data["opponent"]["points"]
TypeError: can only concatenate str (not "int") to str
2019-09-10 15:52:59,704 - metegol - ERROR - can only concatenate str (not "int") to str
Traceback (most recent call last):
  File "/Users/juanpirossi/Documents/personal-projects/metegolBotTelegram/src/utils.py", line 30, in func_wrapper
    func(*args, **kwargs)
  File "/Users/juanpirossi/Documents/personal-projects/metegolBotTelegram/src/callbacks.py", line 22, in inline_button_callback
    _submit_score(bot, data, update.callback_query.message.chat_id)
  File "/Users/juanpirossi/Documents/personal-projects/metegolBotTelegram/src/games.py", line 162, in _submit_score
    ": " + data["opponent"]["points"]
TypeError: can only concatenate str (not "int") to str
2019-09-10 15:52:59,704 - metegol - ERROR - can only concatenate str (not "int") to str
Traceback (most recent call last):
  File "/Users/juanpirossi/Documents/personal-projects/metegolBotTelegram/src/utils.py", line 30, in func_wrapper
    func(*args, **kwargs)
  File "/Users/juanpirossi/Documents/personal-projects/metegolBotTelegram/src/callbacks.py", line 22, in inline_button_callback
    _submit_score(bot, data, update.callback_query.message.chat_id)
  File "/Users/juanpirossi/Documents/personal-projects/metegolBotTelegram/src/games.py", line 162, in _submit_score
    ": " + data["opponent"]["points"]
TypeError: can only concatenate str (not "int") to str
2019-09-10 15:52:59,704 - metegol - ERROR - can only concatenate str (not "int") to str
Traceback (most recent call last):
  File "/Users/juanpirossi/Documents/personal-projects/metegolBotTelegram/src/utils.py", line 30, in func_wrapper
    func(*args, **kwargs)
  File "/Users/juanpirossi/Documents/personal-projects/metegolBotTelegram/src/callbacks.py", line 22, in inline_button_callback
    _submit_score(bot, data, update.callback_query.message.chat_id)
  File "/Users/juanpirossi/Documents/personal-projects/metegolBotTelegram/src/games.py", line 162, in _submit_score
    ": " + data["opponent"]["points"]
TypeError: can only concatenate str (not "int") to str
2019-09-10 15:52:59,704 - metegol - ERROR - can only concatenate str (not "int") to str
Traceback (most recent call last):
  File "/Users/juanpirossi/Documents/personal-projects/metegolBotTelegram/src/utils.py", line 30, in func_wrapper
    func(*args, **kwargs)
  File "/Users/juanpirossi/Documents/personal-projects/metegolBotTelegram/src/callbacks.py", line 22, in inline_button_callback
    _submit_score(bot, data, update.callback_query.message.chat_id)
  File "/Users/juanpirossi/Documents/personal-projects/metegolBotTelegram/src/games.py", line 162, in _submit_score
    ": " + data["opponent"]["points"]
TypeError: can only concatenate str (not "int") to str
2019-09-10 15:58:57,009 - metegol - ERROR - string indices must be integers
Traceback (most recent call last):
  File "/Users/juanpirossi/Documents/personal-projects/metegolBotTelegram/src/utils.py", line 30, in func_wrapper
    func(*args, **kwargs)
  File "/Users/juanpirossi/Documents/personal-projects/metegolBotTelegram/src/callbacks.py", line 14, in inline_button_callback
    _get_player_statics(bot, data, update.callback_query.message.chat_id)
  File "/Users/juanpirossi/Documents/personal-projects/metegolBotTelegram/src/players.py", line 53, in _get_player_statics
    for game in player["games"]:
TypeError: string indices must be integers
2019-09-10 15:58:57,009 - metegol - ERROR - string indices must be integers
Traceback (most recent call last):
  File "/Users/juanpirossi/Documents/personal-projects/metegolBotTelegram/src/utils.py", line 30, in func_wrapper
    func(*args, **kwargs)
  File "/Users/juanpirossi/Documents/personal-projects/metegolBotTelegram/src/callbacks.py", line 14, in inline_button_callback
    _get_player_statics(bot, data, update.callback_query.message.chat_id)
  File "/Users/juanpirossi/Documents/personal-projects/metegolBotTelegram/src/players.py", line 53, in _get_player_statics
    for game in player["games"]:
TypeError: string indices must be integers
2019-09-10 15:59:21,315 - metegol - ERROR - index 'games' cannot be applied to Cursor instances
Traceback (most recent call last):
  File "/Users/juanpirossi/Documents/personal-projects/metegolBotTelegram/src/utils.py", line 30, in func_wrapper
    func(*args, **kwargs)
  File "/Users/juanpirossi/Documents/personal-projects/metegolBotTelegram/src/callbacks.py", line 14, in inline_button_callback
    _get_player_statics(bot, data, update.callback_query.message.chat_id)
  File "/Users/juanpirossi/Documents/personal-projects/metegolBotTelegram/src/players.py", line 53, in _get_player_statics
    for game in user["games"]:
  File "/usr/local/lib/python3.7/site-packages/pymongo/cursor.py", line 618, in __getitem__
    "instances" % index)
TypeError: index 'games' cannot be applied to Cursor instances
2019-09-10 15:59:21,315 - metegol - ERROR - index 'games' cannot be applied to Cursor instances
Traceback (most recent call last):
  File "/Users/juanpirossi/Documents/personal-projects/metegolBotTelegram/src/utils.py", line 30, in func_wrapper
    func(*args, **kwargs)
  File "/Users/juanpirossi/Documents/personal-projects/metegolBotTelegram/src/callbacks.py", line 14, in inline_button_callback
    _get_player_statics(bot, data, update.callback_query.message.chat_id)
  File "/Users/juanpirossi/Documents/personal-projects/metegolBotTelegram/src/players.py", line 53, in _get_player_statics
    for game in user["games"]:
  File "/usr/local/lib/python3.7/site-packages/pymongo/cursor.py", line 618, in __getitem__
    "instances" % index)
TypeError: index 'games' cannot be applied to Cursor instances
2019-09-11 10:03:40,868 - metegol - ERROR - MISCONF Redis is configured to save RDB snapshots, but it is currently not able to persist on disk. Commands that may modify the data set are disabled, because this instance is configured to report errors during writes if RDB snapshotting fails (stop-writes-on-bgsave-error option). Please check the Redis logs for details about the RDB error.
Traceback (most recent call last):
  File "/Users/juanpirossi/Documents/personal-projects/metegolBotTelegram/src/utils.py", line 30, in func_wrapper
    func(*args, **kwargs)
  File "/Users/juanpirossi/Documents/personal-projects/metegolBotTelegram/src/games.py", line 56, in submit_dobles
    uid = redis_set(json.dumps(data))
  File "/Users/juanpirossi/Documents/personal-projects/metegolBotTelegram/src/utils.py", line 15, in redis_set
    r.set(uid, value, ex=300)
  File "/usr/local/lib/python3.7/site-packages/redis/client.py", line 1519, in set
    return self.execute_command('SET', *pieces)
  File "/usr/local/lib/python3.7/site-packages/redis/client.py", line 839, in execute_command
    return self.parse_response(conn, command_name, **options)
  File "/usr/local/lib/python3.7/site-packages/redis/client.py", line 853, in parse_response
    response = connection.read_response()
  File "/usr/local/lib/python3.7/site-packages/redis/connection.py", line 717, in read_response
    raise response
redis.exceptions.ResponseError: MISCONF Redis is configured to save RDB snapshots, but it is currently not able to persist on disk. Commands that may modify the data set are disabled, because this instance is configured to report errors during writes if RDB snapshotting fails (stop-writes-on-bgsave-error option). Please check the Redis logs for details about the RDB error.
2019-09-11 10:03:40,868 - metegol - ERROR - MISCONF Redis is configured to save RDB snapshots, but it is currently not able to persist on disk. Commands that may modify the data set are disabled, because this instance is configured to report errors during writes if RDB snapshotting fails (stop-writes-on-bgsave-error option). Please check the Redis logs for details about the RDB error.
Traceback (most recent call last):
  File "/Users/juanpirossi/Documents/personal-projects/metegolBotTelegram/src/utils.py", line 30, in func_wrapper
    func(*args, **kwargs)
  File "/Users/juanpirossi/Documents/personal-projects/metegolBotTelegram/src/games.py", line 56, in submit_dobles
    uid = redis_set(json.dumps(data))
  File "/Users/juanpirossi/Documents/personal-projects/metegolBotTelegram/src/utils.py", line 15, in redis_set
    r.set(uid, value, ex=300)
  File "/usr/local/lib/python3.7/site-packages/redis/client.py", line 1519, in set
    return self.execute_command('SET', *pieces)
  File "/usr/local/lib/python3.7/site-packages/redis/client.py", line 839, in execute_command
    return self.parse_response(conn, command_name, **options)
  File "/usr/local/lib/python3.7/site-packages/redis/client.py", line 853, in parse_response
    response = connection.read_response()
  File "/usr/local/lib/python3.7/site-packages/redis/connection.py", line 717, in read_response
    raise response
redis.exceptions.ResponseError: MISCONF Redis is configured to save RDB snapshots, but it is currently not able to persist on disk. Commands that may modify the data set are disabled, because this instance is configured to report errors during writes if RDB snapshotting fails (stop-writes-on-bgsave-error option). Please check the Redis logs for details about the RDB error.
2019-09-11 10:03:40,868 - metegol - ERROR - MISCONF Redis is configured to save RDB snapshots, but it is currently not able to persist on disk. Commands that may modify the data set are disabled, because this instance is configured to report errors during writes if RDB snapshotting fails (stop-writes-on-bgsave-error option). Please check the Redis logs for details about the RDB error.
Traceback (most recent call last):
  File "/Users/juanpirossi/Documents/personal-projects/metegolBotTelegram/src/utils.py", line 30, in func_wrapper
    func(*args, **kwargs)
  File "/Users/juanpirossi/Documents/personal-projects/metegolBotTelegram/src/games.py", line 56, in submit_dobles
    uid = redis_set(json.dumps(data))
  File "/Users/juanpirossi/Documents/personal-projects/metegolBotTelegram/src/utils.py", line 15, in redis_set
    r.set(uid, value, ex=300)
  File "/usr/local/lib/python3.7/site-packages/redis/client.py", line 1519, in set
    return self.execute_command('SET', *pieces)
  File "/usr/local/lib/python3.7/site-packages/redis/client.py", line 839, in execute_command
    return self.parse_response(conn, command_name, **options)
  File "/usr/local/lib/python3.7/site-packages/redis/client.py", line 853, in parse_response
    response = connection.read_response()
  File "/usr/local/lib/python3.7/site-packages/redis/connection.py", line 717, in read_response
    raise response
redis.exceptions.ResponseError: MISCONF Redis is configured to save RDB snapshots, but it is currently not able to persist on disk. Commands that may modify the data set are disabled, because this instance is configured to report errors during writes if RDB snapshotting fails (stop-writes-on-bgsave-error option). Please check the Redis logs for details about the RDB error.
2019-09-11 10:03:40,868 - metegol - ERROR - MISCONF Redis is configured to save RDB snapshots, but it is currently not able to persist on disk. Commands that may modify the data set are disabled, because this instance is configured to report errors during writes if RDB snapshotting fails (stop-writes-on-bgsave-error option). Please check the Redis logs for details about the RDB error.
Traceback (most recent call last):
  File "/Users/juanpirossi/Documents/personal-projects/metegolBotTelegram/src/utils.py", line 30, in func_wrapper
    func(*args, **kwargs)
  File "/Users/juanpirossi/Documents/personal-projects/metegolBotTelegram/src/games.py", line 56, in submit_dobles
    uid = redis_set(json.dumps(data))
  File "/Users/juanpirossi/Documents/personal-projects/metegolBotTelegram/src/utils.py", line 15, in redis_set
    r.set(uid, value, ex=300)
  File "/usr/local/lib/python3.7/site-packages/redis/client.py", line 1519, in set
    return self.execute_command('SET', *pieces)
  File "/usr/local/lib/python3.7/site-packages/redis/client.py", line 839, in execute_command
    return self.parse_response(conn, command_name, **options)
  File "/usr/local/lib/python3.7/site-packages/redis/client.py", line 853, in parse_response
    response = connection.read_response()
  File "/usr/local/lib/python3.7/site-packages/redis/connection.py", line 717, in read_response
    raise response
redis.exceptions.ResponseError: MISCONF Redis is configured to save RDB snapshots, but it is currently not able to persist on disk. Commands that may modify the data set are disabled, because this instance is configured to report errors during writes if RDB snapshotting fails (stop-writes-on-bgsave-error option). Please check the Redis logs for details about the RDB error.
2019-09-11 11:55:24,111 - metegol - ERROR - MISCONF Redis is configured to save RDB snapshots, but it is currently not able to persist on disk. Commands that may modify the data set are disabled, because this instance is configured to report errors during writes if RDB snapshotting fails (stop-writes-on-bgsave-error option). Please check the Redis logs for details about the RDB error.
Traceback (most recent call last):
  File "/Users/juanpirossi/Documents/personal-projects/metegolBotTelegram/src/utils.py", line 30, in func_wrapper
    func(*args, **kwargs)
  File "/Users/juanpirossi/Documents/personal-projects/metegolBotTelegram/src/games.py", line 28, in submit
    uid = redis_set(json.dumps(data))
  File "/Users/juanpirossi/Documents/personal-projects/metegolBotTelegram/src/utils.py", line 15, in redis_set
    r.set(uid, value, ex=300)
  File "/usr/local/lib/python3.7/site-packages/redis/client.py", line 1519, in set
    return self.execute_command('SET', *pieces)
  File "/usr/local/lib/python3.7/site-packages/redis/client.py", line 839, in execute_command
    return self.parse_response(conn, command_name, **options)
  File "/usr/local/lib/python3.7/site-packages/redis/client.py", line 853, in parse_response
    response = connection.read_response()
  File "/usr/local/lib/python3.7/site-packages/redis/connection.py", line 717, in read_response
    raise response
redis.exceptions.ResponseError: MISCONF Redis is configured to save RDB snapshots, but it is currently not able to persist on disk. Commands that may modify the data set are disabled, because this instance is configured to report errors during writes if RDB snapshotting fails (stop-writes-on-bgsave-error option). Please check the Redis logs for details about the RDB error.
2019-09-11 11:55:55,176 - metegol - ERROR - submit() takes 2 positional arguments but 3 were given
Traceback (most recent call last):
  File "/Users/juanpirossi/Documents/personal-projects/metegolBotTelegram/src/utils.py", line 30, in func_wrapper
    func(*args, **kwargs)
  File "/Users/juanpirossi/Documents/personal-projects/metegolBotTelegram/src/callbacks.py", line 28, in inline_button_callback
    _submit_confirm(bot, data, update.callback_query.message.chat_id)
  File "/Users/juanpirossi/Documents/personal-projects/metegolBotTelegram/src/games.py", line 194, in _submit_confirm
    _send_elo_changes(bot, player, own_elo_offset, game)
  File "/Users/juanpirossi/Documents/personal-projects/metegolBotTelegram/src/games.py", line 218, in _send_elo_changes
    weekly.submit(player, elo_offset, game)
TypeError: submit() takes 2 positional arguments but 3 were given
2019-09-11 11:55:55,176 - metegol - ERROR - submit() takes 2 positional arguments but 3 were given
Traceback (most recent call last):
  File "/Users/juanpirossi/Documents/personal-projects/metegolBotTelegram/src/utils.py", line 30, in func_wrapper
    func(*args, **kwargs)
  File "/Users/juanpirossi/Documents/personal-projects/metegolBotTelegram/src/callbacks.py", line 28, in inline_button_callback
    _submit_confirm(bot, data, update.callback_query.message.chat_id)
  File "/Users/juanpirossi/Documents/personal-projects/metegolBotTelegram/src/games.py", line 194, in _submit_confirm
    _send_elo_changes(bot, player, own_elo_offset, game)
  File "/Users/juanpirossi/Documents/personal-projects/metegolBotTelegram/src/games.py", line 218, in _send_elo_changes
    weekly.submit(player, elo_offset, game)
TypeError: submit() takes 2 positional arguments but 3 were given
2019-09-11 11:55:55,176 - metegol - ERROR - submit() takes 2 positional arguments but 3 were given
Traceback (most recent call last):
  File "/Users/juanpirossi/Documents/personal-projects/metegolBotTelegram/src/utils.py", line 30, in func_wrapper
    func(*args, **kwargs)
  File "/Users/juanpirossi/Documents/personal-projects/metegolBotTelegram/src/callbacks.py", line 28, in inline_button_callback
    _submit_confirm(bot, data, update.callback_query.message.chat_id)
  File "/Users/juanpirossi/Documents/personal-projects/metegolBotTelegram/src/games.py", line 194, in _submit_confirm
    _send_elo_changes(bot, player, own_elo_offset, game)
  File "/Users/juanpirossi/Documents/personal-projects/metegolBotTelegram/src/games.py", line 218, in _send_elo_changes
    weekly.submit(player, elo_offset, game)
TypeError: submit() takes 2 positional arguments but 3 were given
2019-09-11 11:55:55,176 - metegol - ERROR - submit() takes 2 positional arguments but 3 were given
Traceback (most recent call last):
  File "/Users/juanpirossi/Documents/personal-projects/metegolBotTelegram/src/utils.py", line 30, in func_wrapper
    func(*args, **kwargs)
  File "/Users/juanpirossi/Documents/personal-projects/metegolBotTelegram/src/callbacks.py", line 28, in inline_button_callback
    _submit_confirm(bot, data, update.callback_query.message.chat_id)
  File "/Users/juanpirossi/Documents/personal-projects/metegolBotTelegram/src/games.py", line 194, in _submit_confirm
    _send_elo_changes(bot, player, own_elo_offset, game)
  File "/Users/juanpirossi/Documents/personal-projects/metegolBotTelegram/src/games.py", line 218, in _send_elo_changes
    weekly.submit(player, elo_offset, game)
TypeError: submit() takes 2 positional arguments but 3 were given
2019-09-11 11:55:55,176 - metegol - ERROR - submit() takes 2 positional arguments but 3 were given
Traceback (most recent call last):
  File "/Users/juanpirossi/Documents/personal-projects/metegolBotTelegram/src/utils.py", line 30, in func_wrapper
    func(*args, **kwargs)
  File "/Users/juanpirossi/Documents/personal-projects/metegolBotTelegram/src/callbacks.py", line 28, in inline_button_callback
    _submit_confirm(bot, data, update.callback_query.message.chat_id)
  File "/Users/juanpirossi/Documents/personal-projects/metegolBotTelegram/src/games.py", line 194, in _submit_confirm
    _send_elo_changes(bot, player, own_elo_offset, game)
  File "/Users/juanpirossi/Documents/personal-projects/metegolBotTelegram/src/games.py", line 218, in _send_elo_changes
    weekly.submit(player, elo_offset, game)
TypeError: submit() takes 2 positional arguments but 3 were given
2019-09-11 11:55:55,176 - metegol - ERROR - submit() takes 2 positional arguments but 3 were given
Traceback (most recent call last):
  File "/Users/juanpirossi/Documents/personal-projects/metegolBotTelegram/src/utils.py", line 30, in func_wrapper
    func(*args, **kwargs)
  File "/Users/juanpirossi/Documents/personal-projects/metegolBotTelegram/src/callbacks.py", line 28, in inline_button_callback
    _submit_confirm(bot, data, update.callback_query.message.chat_id)
  File "/Users/juanpirossi/Documents/personal-projects/metegolBotTelegram/src/games.py", line 194, in _submit_confirm
    _send_elo_changes(bot, player, own_elo_offset, game)
  File "/Users/juanpirossi/Documents/personal-projects/metegolBotTelegram/src/games.py", line 218, in _send_elo_changes
    weekly.submit(player, elo_offset, game)
TypeError: submit() takes 2 positional arguments but 3 were given
2019-09-11 11:56:38,321 - metegol - ERROR - name 'config' is not defined
Traceback (most recent call last):
  File "/Users/juanpirossi/Documents/personal-projects/metegolBotTelegram/src/utils.py", line 30, in func_wrapper
    func(*args, **kwargs)
  File "/Users/juanpirossi/Documents/personal-projects/metegolBotTelegram/src/callbacks.py", line 28, in inline_button_callback
    _submit_confirm(bot, data, update.callback_query.message.chat_id)
  File "/Users/juanpirossi/Documents/personal-projects/metegolBotTelegram/src/games.py", line 194, in _submit_confirm
    _send_elo_changes(bot, player, own_elo_offset, game)
  File "/Users/juanpirossi/Documents/personal-projects/metegolBotTelegram/src/games.py", line 218, in _send_elo_changes
    weekly.submit(player, elo_offset, game)
  File "/Users/juanpirossi/Documents/personal-projects/metegolBotTelegram/src/weekly.py", line 9, in submit
    user = mongo.find_one(config.get("WEEKLY_DB"), collection, {"code": user["code"]})
NameError: name 'config' is not defined
2019-09-11 11:56:38,321 - metegol - ERROR - name 'config' is not defined
Traceback (most recent call last):
  File "/Users/juanpirossi/Documents/personal-projects/metegolBotTelegram/src/utils.py", line 30, in func_wrapper
    func(*args, **kwargs)
  File "/Users/juanpirossi/Documents/personal-projects/metegolBotTelegram/src/callbacks.py", line 28, in inline_button_callback
    _submit_confirm(bot, data, update.callback_query.message.chat_id)
  File "/Users/juanpirossi/Documents/personal-projects/metegolBotTelegram/src/games.py", line 194, in _submit_confirm
    _send_elo_changes(bot, player, own_elo_offset, game)
  File "/Users/juanpirossi/Documents/personal-projects/metegolBotTelegram/src/games.py", line 218, in _send_elo_changes
    weekly.submit(player, elo_offset, game)
  File "/Users/juanpirossi/Documents/personal-projects/metegolBotTelegram/src/weekly.py", line 9, in submit
    user = mongo.find_one(config.get("WEEKLY_DB"), collection, {"code": user["code"]})
NameError: name 'config' is not defined
2019-09-11 11:56:38,321 - metegol - ERROR - name 'config' is not defined
Traceback (most recent call last):
  File "/Users/juanpirossi/Documents/personal-projects/metegolBotTelegram/src/utils.py", line 30, in func_wrapper
    func(*args, **kwargs)
  File "/Users/juanpirossi/Documents/personal-projects/metegolBotTelegram/src/callbacks.py", line 28, in inline_button_callback
    _submit_confirm(bot, data, update.callback_query.message.chat_id)
  File "/Users/juanpirossi/Documents/personal-projects/metegolBotTelegram/src/games.py", line 194, in _submit_confirm
    _send_elo_changes(bot, player, own_elo_offset, game)
  File "/Users/juanpirossi/Documents/personal-projects/metegolBotTelegram/src/games.py", line 218, in _send_elo_changes
    weekly.submit(player, elo_offset, game)
  File "/Users/juanpirossi/Documents/personal-projects/metegolBotTelegram/src/weekly.py", line 9, in submit
    user = mongo.find_one(config.get("WEEKLY_DB"), collection, {"code": user["code"]})
NameError: name 'config' is not defined
2019-09-11 11:56:38,321 - metegol - ERROR - name 'config' is not defined
Traceback (most recent call last):
  File "/Users/juanpirossi/Documents/personal-projects/metegolBotTelegram/src/utils.py", line 30, in func_wrapper
    func(*args, **kwargs)
  File "/Users/juanpirossi/Documents/personal-projects/metegolBotTelegram/src/callbacks.py", line 28, in inline_button_callback
    _submit_confirm(bot, data, update.callback_query.message.chat_id)
  File "/Users/juanpirossi/Documents/personal-projects/metegolBotTelegram/src/games.py", line 194, in _submit_confirm
    _send_elo_changes(bot, player, own_elo_offset, game)
  File "/Users/juanpirossi/Documents/personal-projects/metegolBotTelegram/src/games.py", line 218, in _send_elo_changes
    weekly.submit(player, elo_offset, game)
  File "/Users/juanpirossi/Documents/personal-projects/metegolBotTelegram/src/weekly.py", line 9, in submit
    user = mongo.find_one(config.get("WEEKLY_DB"), collection, {"code": user["code"]})
NameError: name 'config' is not defined
2019-09-11 11:56:38,321 - metegol - ERROR - name 'config' is not defined
Traceback (most recent call last):
  File "/Users/juanpirossi/Documents/personal-projects/metegolBotTelegram/src/utils.py", line 30, in func_wrapper
    func(*args, **kwargs)
  File "/Users/juanpirossi/Documents/personal-projects/metegolBotTelegram/src/callbacks.py", line 28, in inline_button_callback
    _submit_confirm(bot, data, update.callback_query.message.chat_id)
  File "/Users/juanpirossi/Documents/personal-projects/metegolBotTelegram/src/games.py", line 194, in _submit_confirm
    _send_elo_changes(bot, player, own_elo_offset, game)
  File "/Users/juanpirossi/Documents/personal-projects/metegolBotTelegram/src/games.py", line 218, in _send_elo_changes
    weekly.submit(player, elo_offset, game)
  File "/Users/juanpirossi/Documents/personal-projects/metegolBotTelegram/src/weekly.py", line 9, in submit
    user = mongo.find_one(config.get("WEEKLY_DB"), collection, {"code": user["code"]})
NameError: name 'config' is not defined
2019-09-11 11:57:10,858 - metegol - ERROR - 'NoneType' object is not subscriptable
Traceback (most recent call last):
  File "/Users/juanpirossi/Documents/personal-projects/metegolBotTelegram/src/utils.py", line 30, in func_wrapper
    func(*args, **kwargs)
  File "/Users/juanpirossi/Documents/personal-projects/metegolBotTelegram/src/callbacks.py", line 28, in inline_button_callback
    _submit_confirm(bot, data, update.callback_query.message.chat_id)
  File "/Users/juanpirossi/Documents/personal-projects/metegolBotTelegram/src/games.py", line 194, in _submit_confirm
    _send_elo_changes(bot, player, own_elo_offset, game)
  File "/Users/juanpirossi/Documents/personal-projects/metegolBotTelegram/src/games.py", line 218, in _send_elo_changes
    weekly.submit(player, elo_offset, game)
  File "/Users/juanpirossi/Documents/personal-projects/metegolBotTelegram/src/weekly.py", line 13, in submit
    "code": user["code"],
TypeError: 'NoneType' object is not subscriptable
2019-09-11 11:57:10,858 - metegol - ERROR - 'NoneType' object is not subscriptable
Traceback (most recent call last):
  File "/Users/juanpirossi/Documents/personal-projects/metegolBotTelegram/src/utils.py", line 30, in func_wrapper
    func(*args, **kwargs)
  File "/Users/juanpirossi/Documents/personal-projects/metegolBotTelegram/src/callbacks.py", line 28, in inline_button_callback
    _submit_confirm(bot, data, update.callback_query.message.chat_id)
  File "/Users/juanpirossi/Documents/personal-projects/metegolBotTelegram/src/games.py", line 194, in _submit_confirm
    _send_elo_changes(bot, player, own_elo_offset, game)
  File "/Users/juanpirossi/Documents/personal-projects/metegolBotTelegram/src/games.py", line 218, in _send_elo_changes
    weekly.submit(player, elo_offset, game)
  File "/Users/juanpirossi/Documents/personal-projects/metegolBotTelegram/src/weekly.py", line 13, in submit
    "code": user["code"],
TypeError: 'NoneType' object is not subscriptable
2019-09-11 11:57:10,858 - metegol - ERROR - 'NoneType' object is not subscriptable
Traceback (most recent call last):
  File "/Users/juanpirossi/Documents/personal-projects/metegolBotTelegram/src/utils.py", line 30, in func_wrapper
    func(*args, **kwargs)
  File "/Users/juanpirossi/Documents/personal-projects/metegolBotTelegram/src/callbacks.py", line 28, in inline_button_callback
    _submit_confirm(bot, data, update.callback_query.message.chat_id)
  File "/Users/juanpirossi/Documents/personal-projects/metegolBotTelegram/src/games.py", line 194, in _submit_confirm
    _send_elo_changes(bot, player, own_elo_offset, game)
  File "/Users/juanpirossi/Documents/personal-projects/metegolBotTelegram/src/games.py", line 218, in _send_elo_changes
    weekly.submit(player, elo_offset, game)
  File "/Users/juanpirossi/Documents/personal-projects/metegolBotTelegram/src/weekly.py", line 13, in submit
    "code": user["code"],
TypeError: 'NoneType' object is not subscriptable
2019-09-11 11:57:10,858 - metegol - ERROR - 'NoneType' object is not subscriptable
Traceback (most recent call last):
  File "/Users/juanpirossi/Documents/personal-projects/metegolBotTelegram/src/utils.py", line 30, in func_wrapper
    func(*args, **kwargs)
  File "/Users/juanpirossi/Documents/personal-projects/metegolBotTelegram/src/callbacks.py", line 28, in inline_button_callback
    _submit_confirm(bot, data, update.callback_query.message.chat_id)
  File "/Users/juanpirossi/Documents/personal-projects/metegolBotTelegram/src/games.py", line 194, in _submit_confirm
    _send_elo_changes(bot, player, own_elo_offset, game)
  File "/Users/juanpirossi/Documents/personal-projects/metegolBotTelegram/src/games.py", line 218, in _send_elo_changes
    weekly.submit(player, elo_offset, game)
  File "/Users/juanpirossi/Documents/personal-projects/metegolBotTelegram/src/weekly.py", line 13, in submit
    "code": user["code"],
TypeError: 'NoneType' object is not subscriptable
2019-09-11 11:57:10,858 - metegol - ERROR - 'NoneType' object is not subscriptable
Traceback (most recent call last):
  File "/Users/juanpirossi/Documents/personal-projects/metegolBotTelegram/src/utils.py", line 30, in func_wrapper
    func(*args, **kwargs)
  File "/Users/juanpirossi/Documents/personal-projects/metegolBotTelegram/src/callbacks.py", line 28, in inline_button_callback
    _submit_confirm(bot, data, update.callback_query.message.chat_id)
  File "/Users/juanpirossi/Documents/personal-projects/metegolBotTelegram/src/games.py", line 194, in _submit_confirm
    _send_elo_changes(bot, player, own_elo_offset, game)
  File "/Users/juanpirossi/Documents/personal-projects/metegolBotTelegram/src/games.py", line 218, in _send_elo_changes
    weekly.submit(player, elo_offset, game)
  File "/Users/juanpirossi/Documents/personal-projects/metegolBotTelegram/src/weekly.py", line 13, in submit
    "code": user["code"],
TypeError: 'NoneType' object is not subscriptable
2019-09-11 12:01:14,008 - metegol - ERROR - MISCONF Redis is configured to save RDB snapshots, but it is currently not able to persist on disk. Commands that may modify the data set are disabled, because this instance is configured to report errors during writes if RDB snapshotting fails (stop-writes-on-bgsave-error option). Please check the Redis logs for details about the RDB error.
Traceback (most recent call last):
  File "/Users/juanpirossi/Documents/personal-projects/metegolBotTelegram/src/utils.py", line 30, in func_wrapper
    func(*args, **kwargs)
  File "/Users/juanpirossi/Documents/personal-projects/metegolBotTelegram/src/games.py", line 28, in submit
    uid = redis_set(json.dumps(data))
  File "/Users/juanpirossi/Documents/personal-projects/metegolBotTelegram/src/utils.py", line 15, in redis_set
    r.set(uid, value, ex=300)
  File "/usr/local/lib/python3.7/site-packages/redis/client.py", line 1519, in set
    return self.execute_command('SET', *pieces)
  File "/usr/local/lib/python3.7/site-packages/redis/client.py", line 839, in execute_command
    return self.parse_response(conn, command_name, **options)
  File "/usr/local/lib/python3.7/site-packages/redis/client.py", line 853, in parse_response
    response = connection.read_response()
  File "/usr/local/lib/python3.7/site-packages/redis/connection.py", line 717, in read_response
    raise response
redis.exceptions.ResponseError: MISCONF Redis is configured to save RDB snapshots, but it is currently not able to persist on disk. Commands that may modify the data set are disabled, because this instance is configured to report errors during writes if RDB snapshotting fails (stop-writes-on-bgsave-error option). Please check the Redis logs for details about the RDB error.
2019-09-11 12:01:14,008 - metegol - ERROR - MISCONF Redis is configured to save RDB snapshots, but it is currently not able to persist on disk. Commands that may modify the data set are disabled, because this instance is configured to report errors during writes if RDB snapshotting fails (stop-writes-on-bgsave-error option). Please check the Redis logs for details about the RDB error.
Traceback (most recent call last):
  File "/Users/juanpirossi/Documents/personal-projects/metegolBotTelegram/src/utils.py", line 30, in func_wrapper
    func(*args, **kwargs)
  File "/Users/juanpirossi/Documents/personal-projects/metegolBotTelegram/src/games.py", line 28, in submit
    uid = redis_set(json.dumps(data))
  File "/Users/juanpirossi/Documents/personal-projects/metegolBotTelegram/src/utils.py", line 15, in redis_set
    r.set(uid, value, ex=300)
  File "/usr/local/lib/python3.7/site-packages/redis/client.py", line 1519, in set
    return self.execute_command('SET', *pieces)
  File "/usr/local/lib/python3.7/site-packages/redis/client.py", line 839, in execute_command
    return self.parse_response(conn, command_name, **options)
  File "/usr/local/lib/python3.7/site-packages/redis/client.py", line 853, in parse_response
    response = connection.read_response()
  File "/usr/local/lib/python3.7/site-packages/redis/connection.py", line 717, in read_response
    raise response
redis.exceptions.ResponseError: MISCONF Redis is configured to save RDB snapshots, but it is currently not able to persist on disk. Commands that may modify the data set are disabled, because this instance is configured to report errors during writes if RDB snapshotting fails (stop-writes-on-bgsave-error option). Please check the Redis logs for details about the RDB error.
2019-09-11 12:01:14,008 - metegol - ERROR - MISCONF Redis is configured to save RDB snapshots, but it is currently not able to persist on disk. Commands that may modify the data set are disabled, because this instance is configured to report errors during writes if RDB snapshotting fails (stop-writes-on-bgsave-error option). Please check the Redis logs for details about the RDB error.
Traceback (most recent call last):
  File "/Users/juanpirossi/Documents/personal-projects/metegolBotTelegram/src/utils.py", line 30, in func_wrapper
    func(*args, **kwargs)
  File "/Users/juanpirossi/Documents/personal-projects/metegolBotTelegram/src/games.py", line 28, in submit
    uid = redis_set(json.dumps(data))
  File "/Users/juanpirossi/Documents/personal-projects/metegolBotTelegram/src/utils.py", line 15, in redis_set
    r.set(uid, value, ex=300)
  File "/usr/local/lib/python3.7/site-packages/redis/client.py", line 1519, in set
    return self.execute_command('SET', *pieces)
  File "/usr/local/lib/python3.7/site-packages/redis/client.py", line 839, in execute_command
    return self.parse_response(conn, command_name, **options)
  File "/usr/local/lib/python3.7/site-packages/redis/client.py", line 853, in parse_response
    response = connection.read_response()
  File "/usr/local/lib/python3.7/site-packages/redis/connection.py", line 717, in read_response
    raise response
redis.exceptions.ResponseError: MISCONF Redis is configured to save RDB snapshots, but it is currently not able to persist on disk. Commands that may modify the data set are disabled, because this instance is configured to report errors during writes if RDB snapshotting fails (stop-writes-on-bgsave-error option). Please check the Redis logs for details about the RDB error.
2019-09-11 12:01:14,008 - metegol - ERROR - MISCONF Redis is configured to save RDB snapshots, but it is currently not able to persist on disk. Commands that may modify the data set are disabled, because this instance is configured to report errors during writes if RDB snapshotting fails (stop-writes-on-bgsave-error option). Please check the Redis logs for details about the RDB error.
Traceback (most recent call last):
  File "/Users/juanpirossi/Documents/personal-projects/metegolBotTelegram/src/utils.py", line 30, in func_wrapper
    func(*args, **kwargs)
  File "/Users/juanpirossi/Documents/personal-projects/metegolBotTelegram/src/games.py", line 28, in submit
    uid = redis_set(json.dumps(data))
  File "/Users/juanpirossi/Documents/personal-projects/metegolBotTelegram/src/utils.py", line 15, in redis_set
    r.set(uid, value, ex=300)
  File "/usr/local/lib/python3.7/site-packages/redis/client.py", line 1519, in set
    return self.execute_command('SET', *pieces)
  File "/usr/local/lib/python3.7/site-packages/redis/client.py", line 839, in execute_command
    return self.parse_response(conn, command_name, **options)
  File "/usr/local/lib/python3.7/site-packages/redis/client.py", line 853, in parse_response
    response = connection.read_response()
  File "/usr/local/lib/python3.7/site-packages/redis/connection.py", line 717, in read_response
    raise response
redis.exceptions.ResponseError: MISCONF Redis is configured to save RDB snapshots, but it is currently not able to persist on disk. Commands that may modify the data set are disabled, because this instance is configured to report errors during writes if RDB snapshotting fails (stop-writes-on-bgsave-error option). Please check the Redis logs for details about the RDB error.
2019-09-11 12:01:14,008 - metegol - ERROR - MISCONF Redis is configured to save RDB snapshots, but it is currently not able to persist on disk. Commands that may modify the data set are disabled, because this instance is configured to report errors during writes if RDB snapshotting fails (stop-writes-on-bgsave-error option). Please check the Redis logs for details about the RDB error.
Traceback (most recent call last):
  File "/Users/juanpirossi/Documents/personal-projects/metegolBotTelegram/src/utils.py", line 30, in func_wrapper
    func(*args, **kwargs)
  File "/Users/juanpirossi/Documents/personal-projects/metegolBotTelegram/src/games.py", line 28, in submit
    uid = redis_set(json.dumps(data))
  File "/Users/juanpirossi/Documents/personal-projects/metegolBotTelegram/src/utils.py", line 15, in redis_set
    r.set(uid, value, ex=300)
  File "/usr/local/lib/python3.7/site-packages/redis/client.py", line 1519, in set
    return self.execute_command('SET', *pieces)
  File "/usr/local/lib/python3.7/site-packages/redis/client.py", line 839, in execute_command
    return self.parse_response(conn, command_name, **options)
  File "/usr/local/lib/python3.7/site-packages/redis/client.py", line 853, in parse_response
    response = connection.read_response()
  File "/usr/local/lib/python3.7/site-packages/redis/connection.py", line 717, in read_response
    raise response
redis.exceptions.ResponseError: MISCONF Redis is configured to save RDB snapshots, but it is currently not able to persist on disk. Commands that may modify the data set are disabled, because this instance is configured to report errors during writes if RDB snapshotting fails (stop-writes-on-bgsave-error option). Please check the Redis logs for details about the RDB error.
2019-09-11 12:01:14,008 - metegol - ERROR - MISCONF Redis is configured to save RDB snapshots, but it is currently not able to persist on disk. Commands that may modify the data set are disabled, because this instance is configured to report errors during writes if RDB snapshotting fails (stop-writes-on-bgsave-error option). Please check the Redis logs for details about the RDB error.
Traceback (most recent call last):
  File "/Users/juanpirossi/Documents/personal-projects/metegolBotTelegram/src/utils.py", line 30, in func_wrapper
    func(*args, **kwargs)
  File "/Users/juanpirossi/Documents/personal-projects/metegolBotTelegram/src/games.py", line 28, in submit
    uid = redis_set(json.dumps(data))
  File "/Users/juanpirossi/Documents/personal-projects/metegolBotTelegram/src/utils.py", line 15, in redis_set
    r.set(uid, value, ex=300)
  File "/usr/local/lib/python3.7/site-packages/redis/client.py", line 1519, in set
    return self.execute_command('SET', *pieces)
  File "/usr/local/lib/python3.7/site-packages/redis/client.py", line 839, in execute_command
    return self.parse_response(conn, command_name, **options)
  File "/usr/local/lib/python3.7/site-packages/redis/client.py", line 853, in parse_response
    response = connection.read_response()
  File "/usr/local/lib/python3.7/site-packages/redis/connection.py", line 717, in read_response
    raise response
redis.exceptions.ResponseError: MISCONF Redis is configured to save RDB snapshots, but it is currently not able to persist on disk. Commands that may modify the data set are disabled, because this instance is configured to report errors during writes if RDB snapshotting fails (stop-writes-on-bgsave-error option). Please check the Redis logs for details about the RDB error.
2019-09-11 12:01:14,008 - metegol - ERROR - MISCONF Redis is configured to save RDB snapshots, but it is currently not able to persist on disk. Commands that may modify the data set are disabled, because this instance is configured to report errors during writes if RDB snapshotting fails (stop-writes-on-bgsave-error option). Please check the Redis logs for details about the RDB error.
Traceback (most recent call last):
  File "/Users/juanpirossi/Documents/personal-projects/metegolBotTelegram/src/utils.py", line 30, in func_wrapper
    func(*args, **kwargs)
  File "/Users/juanpirossi/Documents/personal-projects/metegolBotTelegram/src/games.py", line 28, in submit
    uid = redis_set(json.dumps(data))
  File "/Users/juanpirossi/Documents/personal-projects/metegolBotTelegram/src/utils.py", line 15, in redis_set
    r.set(uid, value, ex=300)
  File "/usr/local/lib/python3.7/site-packages/redis/client.py", line 1519, in set
    return self.execute_command('SET', *pieces)
  File "/usr/local/lib/python3.7/site-packages/redis/client.py", line 839, in execute_command
    return self.parse_response(conn, command_name, **options)
  File "/usr/local/lib/python3.7/site-packages/redis/client.py", line 853, in parse_response
    response = connection.read_response()
  File "/usr/local/lib/python3.7/site-packages/redis/connection.py", line 717, in read_response
    raise response
redis.exceptions.ResponseError: MISCONF Redis is configured to save RDB snapshots, but it is currently not able to persist on disk. Commands that may modify the data set are disabled, because this instance is configured to report errors during writes if RDB snapshotting fails (stop-writes-on-bgsave-error option). Please check the Redis logs for details about the RDB error.
2019-09-11 12:01:14,008 - metegol - ERROR - MISCONF Redis is configured to save RDB snapshots, but it is currently not able to persist on disk. Commands that may modify the data set are disabled, because this instance is configured to report errors during writes if RDB snapshotting fails (stop-writes-on-bgsave-error option). Please check the Redis logs for details about the RDB error.
Traceback (most recent call last):
  File "/Users/juanpirossi/Documents/personal-projects/metegolBotTelegram/src/utils.py", line 30, in func_wrapper
    func(*args, **kwargs)
  File "/Users/juanpirossi/Documents/personal-projects/metegolBotTelegram/src/games.py", line 28, in submit
    uid = redis_set(json.dumps(data))
  File "/Users/juanpirossi/Documents/personal-projects/metegolBotTelegram/src/utils.py", line 15, in redis_set
    r.set(uid, value, ex=300)
  File "/usr/local/lib/python3.7/site-packages/redis/client.py", line 1519, in set
    return self.execute_command('SET', *pieces)
  File "/usr/local/lib/python3.7/site-packages/redis/client.py", line 839, in execute_command
    return self.parse_response(conn, command_name, **options)
  File "/usr/local/lib/python3.7/site-packages/redis/client.py", line 853, in parse_response
    response = connection.read_response()
  File "/usr/local/lib/python3.7/site-packages/redis/connection.py", line 717, in read_response
    raise response
redis.exceptions.ResponseError: MISCONF Redis is configured to save RDB snapshots, but it is currently not able to persist on disk. Commands that may modify the data set are disabled, because this instance is configured to report errors during writes if RDB snapshotting fails (stop-writes-on-bgsave-error option). Please check the Redis logs for details about the RDB error.
2019-09-11 12:01:14,008 - metegol - ERROR - MISCONF Redis is configured to save RDB snapshots, but it is currently not able to persist on disk. Commands that may modify the data set are disabled, because this instance is configured to report errors during writes if RDB snapshotting fails (stop-writes-on-bgsave-error option). Please check the Redis logs for details about the RDB error.
Traceback (most recent call last):
  File "/Users/juanpirossi/Documents/personal-projects/metegolBotTelegram/src/utils.py", line 30, in func_wrapper
    func(*args, **kwargs)
  File "/Users/juanpirossi/Documents/personal-projects/metegolBotTelegram/src/games.py", line 28, in submit
    uid = redis_set(json.dumps(data))
  File "/Users/juanpirossi/Documents/personal-projects/metegolBotTelegram/src/utils.py", line 15, in redis_set
    r.set(uid, value, ex=300)
  File "/usr/local/lib/python3.7/site-packages/redis/client.py", line 1519, in set
    return self.execute_command('SET', *pieces)
  File "/usr/local/lib/python3.7/site-packages/redis/client.py", line 839, in execute_command
    return self.parse_response(conn, command_name, **options)
  File "/usr/local/lib/python3.7/site-packages/redis/client.py", line 853, in parse_response
    response = connection.read_response()
  File "/usr/local/lib/python3.7/site-packages/redis/connection.py", line 717, in read_response
    raise response
redis.exceptions.ResponseError: MISCONF Redis is configured to save RDB snapshots, but it is currently not able to persist on disk. Commands that may modify the data set are disabled, because this instance is configured to report errors during writes if RDB snapshotting fails (stop-writes-on-bgsave-error option). Please check the Redis logs for details about the RDB error.
2019-09-11 12:01:14,008 - metegol - ERROR - MISCONF Redis is configured to save RDB snapshots, but it is currently not able to persist on disk. Commands that may modify the data set are disabled, because this instance is configured to report errors during writes if RDB snapshotting fails (stop-writes-on-bgsave-error option). Please check the Redis logs for details about the RDB error.
Traceback (most recent call last):
  File "/Users/juanpirossi/Documents/personal-projects/metegolBotTelegram/src/utils.py", line 30, in func_wrapper
    func(*args, **kwargs)
  File "/Users/juanpirossi/Documents/personal-projects/metegolBotTelegram/src/games.py", line 28, in submit
    uid = redis_set(json.dumps(data))
  File "/Users/juanpirossi/Documents/personal-projects/metegolBotTelegram/src/utils.py", line 15, in redis_set
    r.set(uid, value, ex=300)
  File "/usr/local/lib/python3.7/site-packages/redis/client.py", line 1519, in set
    return self.execute_command('SET', *pieces)
  File "/usr/local/lib/python3.7/site-packages/redis/client.py", line 839, in execute_command
    return self.parse_response(conn, command_name, **options)
  File "/usr/local/lib/python3.7/site-packages/redis/client.py", line 853, in parse_response
    response = connection.read_response()
  File "/usr/local/lib/python3.7/site-packages/redis/connection.py", line 717, in read_response
    raise response
redis.exceptions.ResponseError: MISCONF Redis is configured to save RDB snapshots, but it is currently not able to persist on disk. Commands that may modify the data set are disabled, because this instance is configured to report errors during writes if RDB snapshotting fails (stop-writes-on-bgsave-error option). Please check the Redis logs for details about the RDB error.
2019-09-11 12:01:14,008 - metegol - ERROR - MISCONF Redis is configured to save RDB snapshots, but it is currently not able to persist on disk. Commands that may modify the data set are disabled, because this instance is configured to report errors during writes if RDB snapshotting fails (stop-writes-on-bgsave-error option). Please check the Redis logs for details about the RDB error.
Traceback (most recent call last):
  File "/Users/juanpirossi/Documents/personal-projects/metegolBotTelegram/src/utils.py", line 30, in func_wrapper
    func(*args, **kwargs)
  File "/Users/juanpirossi/Documents/personal-projects/metegolBotTelegram/src/games.py", line 28, in submit
    uid = redis_set(json.dumps(data))
  File "/Users/juanpirossi/Documents/personal-projects/metegolBotTelegram/src/utils.py", line 15, in redis_set
    r.set(uid, value, ex=300)
  File "/usr/local/lib/python3.7/site-packages/redis/client.py", line 1519, in set
    return self.execute_command('SET', *pieces)
  File "/usr/local/lib/python3.7/site-packages/redis/client.py", line 839, in execute_command
    return self.parse_response(conn, command_name, **options)
  File "/usr/local/lib/python3.7/site-packages/redis/client.py", line 853, in parse_response
    response = connection.read_response()
  File "/usr/local/lib/python3.7/site-packages/redis/connection.py", line 717, in read_response
    raise response
redis.exceptions.ResponseError: MISCONF Redis is configured to save RDB snapshots, but it is currently not able to persist on disk. Commands that may modify the data set are disabled, because this instance is configured to report errors during writes if RDB snapshotting fails (stop-writes-on-bgsave-error option). Please check the Redis logs for details about the RDB error.
2019-09-11 12:13:08,486 - metegol - ERROR - name '_send_ranking' is not defined
Traceback (most recent call last):
  File "/Users/juanpirossi/Documents/personal-projects/metegolBotTelegram/src/utils.py", line 30, in func_wrapper
    func(*args, **kwargs)
  File "/Users/juanpirossi/Documents/personal-projects/metegolBotTelegram/src/weekly.py", line 29, in ranking
    _send_ranking(bot, update.message.chat_id, config.get("WEEKLY_DB"))
NameError: name '_send_ranking' is not defined
2019-09-11 12:13:43,749 - metegol - ERROR - 'function' object has no attribute '_send_ranking'
Traceback (most recent call last):
  File "/Users/juanpirossi/Documents/personal-projects/metegolBotTelegram/src/utils.py", line 30, in func_wrapper
    func(*args, **kwargs)
  File "/Users/juanpirossi/Documents/personal-projects/metegolBotTelegram/src/weekly.py", line 30, in ranking
    ranking._send_ranking(bot, update.message.chat_id, config.get("WEEKLY_DB"))
AttributeError: 'function' object has no attribute '_send_ranking'
2019-09-11 12:16:26,025 - metegol - ERROR - MISCONF Redis is configured to save RDB snapshots, but it is currently not able to persist on disk. Commands that may modify the data set are disabled, because this instance is configured to report errors during writes if RDB snapshotting fails (stop-writes-on-bgsave-error option). Please check the Redis logs for details about the RDB error.
Traceback (most recent call last):
  File "/Users/juanpirossi/Documents/personal-projects/metegolBotTelegram/src/utils.py", line 30, in func_wrapper
    func(*args, **kwargs)
  File "/Users/juanpirossi/Documents/personal-projects/metegolBotTelegram/src/games.py", line 28, in submit
    uid = redis_set(json.dumps(data))
  File "/Users/juanpirossi/Documents/personal-projects/metegolBotTelegram/src/utils.py", line 15, in redis_set
    r.set(uid, value, ex=300)
  File "/usr/local/lib/python3.7/site-packages/redis/client.py", line 1519, in set
    return self.execute_command('SET', *pieces)
  File "/usr/local/lib/python3.7/site-packages/redis/client.py", line 839, in execute_command
    return self.parse_response(conn, command_name, **options)
  File "/usr/local/lib/python3.7/site-packages/redis/client.py", line 853, in parse_response
    response = connection.read_response()
  File "/usr/local/lib/python3.7/site-packages/redis/connection.py", line 717, in read_response
    raise response
redis.exceptions.ResponseError: MISCONF Redis is configured to save RDB snapshots, but it is currently not able to persist on disk. Commands that may modify the data set are disabled, because this instance is configured to report errors during writes if RDB snapshotting fails (stop-writes-on-bgsave-error option). Please check the Redis logs for details about the RDB error.
2019-09-11 12:16:26,025 - metegol - ERROR - MISCONF Redis is configured to save RDB snapshots, but it is currently not able to persist on disk. Commands that may modify the data set are disabled, because this instance is configured to report errors during writes if RDB snapshotting fails (stop-writes-on-bgsave-error option). Please check the Redis logs for details about the RDB error.
Traceback (most recent call last):
  File "/Users/juanpirossi/Documents/personal-projects/metegolBotTelegram/src/utils.py", line 30, in func_wrapper
    func(*args, **kwargs)
  File "/Users/juanpirossi/Documents/personal-projects/metegolBotTelegram/src/games.py", line 28, in submit
    uid = redis_set(json.dumps(data))
  File "/Users/juanpirossi/Documents/personal-projects/metegolBotTelegram/src/utils.py", line 15, in redis_set
    r.set(uid, value, ex=300)
  File "/usr/local/lib/python3.7/site-packages/redis/client.py", line 1519, in set
    return self.execute_command('SET', *pieces)
  File "/usr/local/lib/python3.7/site-packages/redis/client.py", line 839, in execute_command
    return self.parse_response(conn, command_name, **options)
  File "/usr/local/lib/python3.7/site-packages/redis/client.py", line 853, in parse_response
    response = connection.read_response()
  File "/usr/local/lib/python3.7/site-packages/redis/connection.py", line 717, in read_response
    raise response
redis.exceptions.ResponseError: MISCONF Redis is configured to save RDB snapshots, but it is currently not able to persist on disk. Commands that may modify the data set are disabled, because this instance is configured to report errors during writes if RDB snapshotting fails (stop-writes-on-bgsave-error option). Please check the Redis logs for details about the RDB error.
2019-09-11 12:16:26,025 - metegol - ERROR - MISCONF Redis is configured to save RDB snapshots, but it is currently not able to persist on disk. Commands that may modify the data set are disabled, because this instance is configured to report errors during writes if RDB snapshotting fails (stop-writes-on-bgsave-error option). Please check the Redis logs for details about the RDB error.
Traceback (most recent call last):
  File "/Users/juanpirossi/Documents/personal-projects/metegolBotTelegram/src/utils.py", line 30, in func_wrapper
    func(*args, **kwargs)
  File "/Users/juanpirossi/Documents/personal-projects/metegolBotTelegram/src/games.py", line 28, in submit
    uid = redis_set(json.dumps(data))
  File "/Users/juanpirossi/Documents/personal-projects/metegolBotTelegram/src/utils.py", line 15, in redis_set
    r.set(uid, value, ex=300)
  File "/usr/local/lib/python3.7/site-packages/redis/client.py", line 1519, in set
    return self.execute_command('SET', *pieces)
  File "/usr/local/lib/python3.7/site-packages/redis/client.py", line 839, in execute_command
    return self.parse_response(conn, command_name, **options)
  File "/usr/local/lib/python3.7/site-packages/redis/client.py", line 853, in parse_response
    response = connection.read_response()
  File "/usr/local/lib/python3.7/site-packages/redis/connection.py", line 717, in read_response
    raise response
redis.exceptions.ResponseError: MISCONF Redis is configured to save RDB snapshots, but it is currently not able to persist on disk. Commands that may modify the data set are disabled, because this instance is configured to report errors during writes if RDB snapshotting fails (stop-writes-on-bgsave-error option). Please check the Redis logs for details about the RDB error.
2019-09-11 12:17:06,538 - metegol - ERROR - [Errno 2] No such file or directory: '/var/sources/metegolBotTelegram/8a0.gif'
Traceback (most recent call last):
  File "/Users/juanpirossi/Documents/personal-projects/metegolBotTelegram/src/utils.py", line 30, in func_wrapper
    func(*args, **kwargs)
  File "/Users/juanpirossi/Documents/personal-projects/metegolBotTelegram/src/callbacks.py", line 28, in inline_button_callback
    _submit_confirm(bot, data, update.callback_query.message.chat_id)
  File "/Users/juanpirossi/Documents/personal-projects/metegolBotTelegram/src/games.py", line 208, in _submit_confirm
    if (int(data["own"]["points"]) == 7 and int(data["opponent"]["points"]) == 0) or (int(data["own"]["points"]) == 0 and int(data["opponent"]["points"]) == 7):
FileNotFoundError: [Errno 2] No such file or directory: '/var/sources/metegolBotTelegram/8a0.gif'
2019-09-11 12:17:06,538 - metegol - ERROR - [Errno 2] No such file or directory: '/var/sources/metegolBotTelegram/8a0.gif'
Traceback (most recent call last):
  File "/Users/juanpirossi/Documents/personal-projects/metegolBotTelegram/src/utils.py", line 30, in func_wrapper
    func(*args, **kwargs)
  File "/Users/juanpirossi/Documents/personal-projects/metegolBotTelegram/src/callbacks.py", line 28, in inline_button_callback
    _submit_confirm(bot, data, update.callback_query.message.chat_id)
  File "/Users/juanpirossi/Documents/personal-projects/metegolBotTelegram/src/games.py", line 208, in _submit_confirm
    if (int(data["own"]["points"]) == 7 and int(data["opponent"]["points"]) == 0) or (int(data["own"]["points"]) == 0 and int(data["opponent"]["points"]) == 7):
FileNotFoundError: [Errno 2] No such file or directory: '/var/sources/metegolBotTelegram/8a0.gif'
2019-09-11 12:17:06,538 - metegol - ERROR - [Errno 2] No such file or directory: '/var/sources/metegolBotTelegram/8a0.gif'
Traceback (most recent call last):
  File "/Users/juanpirossi/Documents/personal-projects/metegolBotTelegram/src/utils.py", line 30, in func_wrapper
    func(*args, **kwargs)
  File "/Users/juanpirossi/Documents/personal-projects/metegolBotTelegram/src/callbacks.py", line 28, in inline_button_callback
    _submit_confirm(bot, data, update.callback_query.message.chat_id)
  File "/Users/juanpirossi/Documents/personal-projects/metegolBotTelegram/src/games.py", line 208, in _submit_confirm
    if (int(data["own"]["points"]) == 7 and int(data["opponent"]["points"]) == 0) or (int(data["own"]["points"]) == 0 and int(data["opponent"]["points"]) == 7):
FileNotFoundError: [Errno 2] No such file or directory: '/var/sources/metegolBotTelegram/8a0.gif'
2019-09-11 12:17:06,538 - metegol - ERROR - [Errno 2] No such file or directory: '/var/sources/metegolBotTelegram/8a0.gif'
Traceback (most recent call last):
  File "/Users/juanpirossi/Documents/personal-projects/metegolBotTelegram/src/utils.py", line 30, in func_wrapper
    func(*args, **kwargs)
  File "/Users/juanpirossi/Documents/personal-projects/metegolBotTelegram/src/callbacks.py", line 28, in inline_button_callback
    _submit_confirm(bot, data, update.callback_query.message.chat_id)
  File "/Users/juanpirossi/Documents/personal-projects/metegolBotTelegram/src/games.py", line 208, in _submit_confirm
    if (int(data["own"]["points"]) == 7 and int(data["opponent"]["points"]) == 0) or (int(data["own"]["points"]) == 0 and int(data["opponent"]["points"]) == 7):
FileNotFoundError: [Errno 2] No such file or directory: '/var/sources/metegolBotTelegram/8a0.gif'
2019-09-11 12:17:06,538 - metegol - ERROR - [Errno 2] No such file or directory: '/var/sources/metegolBotTelegram/8a0.gif'
Traceback (most recent call last):
  File "/Users/juanpirossi/Documents/personal-projects/metegolBotTelegram/src/utils.py", line 30, in func_wrapper
    func(*args, **kwargs)
  File "/Users/juanpirossi/Documents/personal-projects/metegolBotTelegram/src/callbacks.py", line 28, in inline_button_callback
    _submit_confirm(bot, data, update.callback_query.message.chat_id)
  File "/Users/juanpirossi/Documents/personal-projects/metegolBotTelegram/src/games.py", line 208, in _submit_confirm
    if (int(data["own"]["points"]) == 7 and int(data["opponent"]["points"]) == 0) or (int(data["own"]["points"]) == 0 and int(data["opponent"]["points"]) == 7):
FileNotFoundError: [Errno 2] No such file or directory: '/var/sources/metegolBotTelegram/8a0.gif'
2019-09-11 12:17:06,538 - metegol - ERROR - [Errno 2] No such file or directory: '/var/sources/metegolBotTelegram/8a0.gif'
Traceback (most recent call last):
  File "/Users/juanpirossi/Documents/personal-projects/metegolBotTelegram/src/utils.py", line 30, in func_wrapper
    func(*args, **kwargs)
  File "/Users/juanpirossi/Documents/personal-projects/metegolBotTelegram/src/callbacks.py", line 28, in inline_button_callback
    _submit_confirm(bot, data, update.callback_query.message.chat_id)
  File "/Users/juanpirossi/Documents/personal-projects/metegolBotTelegram/src/games.py", line 208, in _submit_confirm
    if (int(data["own"]["points"]) == 7 and int(data["opponent"]["points"]) == 0) or (int(data["own"]["points"]) == 0 and int(data["opponent"]["points"]) == 7):
FileNotFoundError: [Errno 2] No such file or directory: '/var/sources/metegolBotTelegram/8a0.gif'
2019-09-11 12:17:06,538 - metegol - ERROR - [Errno 2] No such file or directory: '/var/sources/metegolBotTelegram/8a0.gif'
Traceback (most recent call last):
  File "/Users/juanpirossi/Documents/personal-projects/metegolBotTelegram/src/utils.py", line 30, in func_wrapper
    func(*args, **kwargs)
  File "/Users/juanpirossi/Documents/personal-projects/metegolBotTelegram/src/callbacks.py", line 28, in inline_button_callback
    _submit_confirm(bot, data, update.callback_query.message.chat_id)
  File "/Users/juanpirossi/Documents/personal-projects/metegolBotTelegram/src/games.py", line 208, in _submit_confirm
    if (int(data["own"]["points"]) == 7 and int(data["opponent"]["points"]) == 0) or (int(data["own"]["points"]) == 0 and int(data["opponent"]["points"]) == 7):
FileNotFoundError: [Errno 2] No such file or directory: '/var/sources/metegolBotTelegram/8a0.gif'
2019-09-11 12:17:06,538 - metegol - ERROR - [Errno 2] No such file or directory: '/var/sources/metegolBotTelegram/8a0.gif'
Traceback (most recent call last):
  File "/Users/juanpirossi/Documents/personal-projects/metegolBotTelegram/src/utils.py", line 30, in func_wrapper
    func(*args, **kwargs)
  File "/Users/juanpirossi/Documents/personal-projects/metegolBotTelegram/src/callbacks.py", line 28, in inline_button_callback
    _submit_confirm(bot, data, update.callback_query.message.chat_id)
  File "/Users/juanpirossi/Documents/personal-projects/metegolBotTelegram/src/games.py", line 208, in _submit_confirm
    if (int(data["own"]["points"]) == 7 and int(data["opponent"]["points"]) == 0) or (int(data["own"]["points"]) == 0 and int(data["opponent"]["points"]) == 7):
FileNotFoundError: [Errno 2] No such file or directory: '/var/sources/metegolBotTelegram/8a0.gif'
2019-09-11 12:27:40,894 - metegol - ERROR - MISCONF Redis is configured to save RDB snapshots, but it is currently not able to persist on disk. Commands that may modify the data set are disabled, because this instance is configured to report errors during writes if RDB snapshotting fails (stop-writes-on-bgsave-error option). Please check the Redis logs for details about the RDB error.
Traceback (most recent call last):
  File "/Users/juanpirossi/Documents/personal-projects/metegolBotTelegram/src/utils.py", line 30, in func_wrapper
    func(*args, **kwargs)
  File "/Users/juanpirossi/Documents/personal-projects/metegolBotTelegram/src/games.py", line 28, in submit
    uid = redis_set(json.dumps(data))
  File "/Users/juanpirossi/Documents/personal-projects/metegolBotTelegram/src/utils.py", line 15, in redis_set
    r.set(uid, value, ex=300)
  File "/usr/local/lib/python3.7/site-packages/redis/client.py", line 1519, in set
    return self.execute_command('SET', *pieces)
  File "/usr/local/lib/python3.7/site-packages/redis/client.py", line 839, in execute_command
    return self.parse_response(conn, command_name, **options)
  File "/usr/local/lib/python3.7/site-packages/redis/client.py", line 853, in parse_response
    response = connection.read_response()
  File "/usr/local/lib/python3.7/site-packages/redis/connection.py", line 717, in read_response
    raise response
redis.exceptions.ResponseError: MISCONF Redis is configured to save RDB snapshots, but it is currently not able to persist on disk. Commands that may modify the data set are disabled, because this instance is configured to report errors during writes if RDB snapshotting fails (stop-writes-on-bgsave-error option). Please check the Redis logs for details about the RDB error.
2019-09-11 12:28:18,499 - metegol - ERROR - division by zero
Traceback (most recent call last):
  File "/Users/juanpirossi/Documents/personal-projects/metegolBotTelegram/src/utils.py", line 30, in func_wrapper
    func(*args, **kwargs)
  File "/Users/juanpirossi/Documents/personal-projects/metegolBotTelegram/src/callbacks.py", line 28, in inline_button_callback
    _submit_confirm(bot, data, update.callback_query.message.chat_id)
  File "/Users/juanpirossi/Documents/personal-projects/metegolBotTelegram/src/games.py", line 205, in _submit_confirm
    weekly.submit(data)
  File "/Users/juanpirossi/Documents/personal-projects/metegolBotTelegram/src/weekly.py", line 26, in submit
    opponent_elo = sum([user["ELO"] for user in opponent]) / len(opponent)
ZeroDivisionError: division by zero
2019-09-11 12:28:18,499 - metegol - ERROR - division by zero
Traceback (most recent call last):
  File "/Users/juanpirossi/Documents/personal-projects/metegolBotTelegram/src/utils.py", line 30, in func_wrapper
    func(*args, **kwargs)
  File "/Users/juanpirossi/Documents/personal-projects/metegolBotTelegram/src/callbacks.py", line 28, in inline_button_callback
    _submit_confirm(bot, data, update.callback_query.message.chat_id)
  File "/Users/juanpirossi/Documents/personal-projects/metegolBotTelegram/src/games.py", line 205, in _submit_confirm
    weekly.submit(data)
  File "/Users/juanpirossi/Documents/personal-projects/metegolBotTelegram/src/weekly.py", line 26, in submit
    opponent_elo = sum([user["ELO"] for user in opponent]) / len(opponent)
ZeroDivisionError: division by zero
2019-09-11 12:28:18,499 - metegol - ERROR - division by zero
Traceback (most recent call last):
  File "/Users/juanpirossi/Documents/personal-projects/metegolBotTelegram/src/utils.py", line 30, in func_wrapper
    func(*args, **kwargs)
  File "/Users/juanpirossi/Documents/personal-projects/metegolBotTelegram/src/callbacks.py", line 28, in inline_button_callback
    _submit_confirm(bot, data, update.callback_query.message.chat_id)
  File "/Users/juanpirossi/Documents/personal-projects/metegolBotTelegram/src/games.py", line 205, in _submit_confirm
    weekly.submit(data)
  File "/Users/juanpirossi/Documents/personal-projects/metegolBotTelegram/src/weekly.py", line 26, in submit
    opponent_elo = sum([user["ELO"] for user in opponent]) / len(opponent)
ZeroDivisionError: division by zero
2019-09-11 12:28:18,499 - metegol - ERROR - division by zero
Traceback (most recent call last):
  File "/Users/juanpirossi/Documents/personal-projects/metegolBotTelegram/src/utils.py", line 30, in func_wrapper
    func(*args, **kwargs)
  File "/Users/juanpirossi/Documents/personal-projects/metegolBotTelegram/src/callbacks.py", line 28, in inline_button_callback
    _submit_confirm(bot, data, update.callback_query.message.chat_id)
  File "/Users/juanpirossi/Documents/personal-projects/metegolBotTelegram/src/games.py", line 205, in _submit_confirm
    weekly.submit(data)
  File "/Users/juanpirossi/Documents/personal-projects/metegolBotTelegram/src/weekly.py", line 26, in submit
    opponent_elo = sum([user["ELO"] for user in opponent]) / len(opponent)
ZeroDivisionError: division by zero
2019-09-11 12:28:18,499 - metegol - ERROR - division by zero
Traceback (most recent call last):
  File "/Users/juanpirossi/Documents/personal-projects/metegolBotTelegram/src/utils.py", line 30, in func_wrapper
    func(*args, **kwargs)
  File "/Users/juanpirossi/Documents/personal-projects/metegolBotTelegram/src/callbacks.py", line 28, in inline_button_callback
    _submit_confirm(bot, data, update.callback_query.message.chat_id)
  File "/Users/juanpirossi/Documents/personal-projects/metegolBotTelegram/src/games.py", line 205, in _submit_confirm
    weekly.submit(data)
  File "/Users/juanpirossi/Documents/personal-projects/metegolBotTelegram/src/weekly.py", line 26, in submit
    opponent_elo = sum([user["ELO"] for user in opponent]) / len(opponent)
ZeroDivisionError: division by zero
2019-09-11 12:28:18,499 - metegol - ERROR - division by zero
Traceback (most recent call last):
  File "/Users/juanpirossi/Documents/personal-projects/metegolBotTelegram/src/utils.py", line 30, in func_wrapper
    func(*args, **kwargs)
  File "/Users/juanpirossi/Documents/personal-projects/metegolBotTelegram/src/callbacks.py", line 28, in inline_button_callback
    _submit_confirm(bot, data, update.callback_query.message.chat_id)
  File "/Users/juanpirossi/Documents/personal-projects/metegolBotTelegram/src/games.py", line 205, in _submit_confirm
    weekly.submit(data)
  File "/Users/juanpirossi/Documents/personal-projects/metegolBotTelegram/src/weekly.py", line 26, in submit
    opponent_elo = sum([user["ELO"] for user in opponent]) / len(opponent)
ZeroDivisionError: division by zero
2019-09-11 12:32:46,014 - metegol - ERROR - string indices must be integers
Traceback (most recent call last):
  File "/Users/juanpirossi/Documents/personal-projects/metegolBotTelegram/src/utils.py", line 30, in func_wrapper
    func(*args, **kwargs)
  File "/Users/juanpirossi/Documents/personal-projects/metegolBotTelegram/src/callbacks.py", line 28, in inline_button_callback
    _submit_confirm(bot, data, update.callback_query.message.chat_id)
  File "/Users/juanpirossi/Documents/personal-projects/metegolBotTelegram/src/games.py", line 205, in _submit_confirm
    weekly.submit(data)
  File "/Users/juanpirossi/Documents/personal-projects/metegolBotTelegram/src/weekly.py", line 25, in submit
    "code": player["code"],
TypeError: string indices must be integers
2019-09-11 12:32:46,014 - metegol - ERROR - string indices must be integers
Traceback (most recent call last):
  File "/Users/juanpirossi/Documents/personal-projects/metegolBotTelegram/src/utils.py", line 30, in func_wrapper
    func(*args, **kwargs)
  File "/Users/juanpirossi/Documents/personal-projects/metegolBotTelegram/src/callbacks.py", line 28, in inline_button_callback
    _submit_confirm(bot, data, update.callback_query.message.chat_id)
  File "/Users/juanpirossi/Documents/personal-projects/metegolBotTelegram/src/games.py", line 205, in _submit_confirm
    weekly.submit(data)
  File "/Users/juanpirossi/Documents/personal-projects/metegolBotTelegram/src/weekly.py", line 25, in submit
    "code": player["code"],
TypeError: string indices must be integers
2019-09-11 12:32:46,014 - metegol - ERROR - string indices must be integers
Traceback (most recent call last):
  File "/Users/juanpirossi/Documents/personal-projects/metegolBotTelegram/src/utils.py", line 30, in func_wrapper
    func(*args, **kwargs)
  File "/Users/juanpirossi/Documents/personal-projects/metegolBotTelegram/src/callbacks.py", line 28, in inline_button_callback
    _submit_confirm(bot, data, update.callback_query.message.chat_id)
  File "/Users/juanpirossi/Documents/personal-projects/metegolBotTelegram/src/games.py", line 205, in _submit_confirm
    weekly.submit(data)
  File "/Users/juanpirossi/Documents/personal-projects/metegolBotTelegram/src/weekly.py", line 25, in submit
    "code": player["code"],
TypeError: string indices must be integers
2019-09-11 12:32:46,014 - metegol - ERROR - string indices must be integers
Traceback (most recent call last):
  File "/Users/juanpirossi/Documents/personal-projects/metegolBotTelegram/src/utils.py", line 30, in func_wrapper
    func(*args, **kwargs)
  File "/Users/juanpirossi/Documents/personal-projects/metegolBotTelegram/src/callbacks.py", line 28, in inline_button_callback
    _submit_confirm(bot, data, update.callback_query.message.chat_id)
  File "/Users/juanpirossi/Documents/personal-projects/metegolBotTelegram/src/games.py", line 205, in _submit_confirm
    weekly.submit(data)
  File "/Users/juanpirossi/Documents/personal-projects/metegolBotTelegram/src/weekly.py", line 25, in submit
    "code": player["code"],
TypeError: string indices must be integers
2019-09-11 12:32:46,014 - metegol - ERROR - string indices must be integers
Traceback (most recent call last):
  File "/Users/juanpirossi/Documents/personal-projects/metegolBotTelegram/src/utils.py", line 30, in func_wrapper
    func(*args, **kwargs)
  File "/Users/juanpirossi/Documents/personal-projects/metegolBotTelegram/src/callbacks.py", line 28, in inline_button_callback
    _submit_confirm(bot, data, update.callback_query.message.chat_id)
  File "/Users/juanpirossi/Documents/personal-projects/metegolBotTelegram/src/games.py", line 205, in _submit_confirm
    weekly.submit(data)
  File "/Users/juanpirossi/Documents/personal-projects/metegolBotTelegram/src/weekly.py", line 25, in submit
    "code": player["code"],
TypeError: string indices must be integers
2019-09-11 12:32:46,014 - metegol - ERROR - string indices must be integers
Traceback (most recent call last):
  File "/Users/juanpirossi/Documents/personal-projects/metegolBotTelegram/src/utils.py", line 30, in func_wrapper
    func(*args, **kwargs)
  File "/Users/juanpirossi/Documents/personal-projects/metegolBotTelegram/src/callbacks.py", line 28, in inline_button_callback
    _submit_confirm(bot, data, update.callback_query.message.chat_id)
  File "/Users/juanpirossi/Documents/personal-projects/metegolBotTelegram/src/games.py", line 205, in _submit_confirm
    weekly.submit(data)
  File "/Users/juanpirossi/Documents/personal-projects/metegolBotTelegram/src/weekly.py", line 25, in submit
    "code": player["code"],
TypeError: string indices must be integers
2019-09-11 12:32:46,014 - metegol - ERROR - string indices must be integers
Traceback (most recent call last):
  File "/Users/juanpirossi/Documents/personal-projects/metegolBotTelegram/src/utils.py", line 30, in func_wrapper
    func(*args, **kwargs)
  File "/Users/juanpirossi/Documents/personal-projects/metegolBotTelegram/src/callbacks.py", line 28, in inline_button_callback
    _submit_confirm(bot, data, update.callback_query.message.chat_id)
  File "/Users/juanpirossi/Documents/personal-projects/metegolBotTelegram/src/games.py", line 205, in _submit_confirm
    weekly.submit(data)
  File "/Users/juanpirossi/Documents/personal-projects/metegolBotTelegram/src/weekly.py", line 25, in submit
    "code": player["code"],
TypeError: string indices must be integers
2019-09-11 12:32:46,014 - metegol - ERROR - string indices must be integers
Traceback (most recent call last):
  File "/Users/juanpirossi/Documents/personal-projects/metegolBotTelegram/src/utils.py", line 30, in func_wrapper
    func(*args, **kwargs)
  File "/Users/juanpirossi/Documents/personal-projects/metegolBotTelegram/src/callbacks.py", line 28, in inline_button_callback
    _submit_confirm(bot, data, update.callback_query.message.chat_id)
  File "/Users/juanpirossi/Documents/personal-projects/metegolBotTelegram/src/games.py", line 205, in _submit_confirm
    weekly.submit(data)
  File "/Users/juanpirossi/Documents/personal-projects/metegolBotTelegram/src/weekly.py", line 25, in submit
    "code": player["code"],
TypeError: string indices must be integers
2019-09-11 12:32:46,014 - metegol - ERROR - string indices must be integers
Traceback (most recent call last):
  File "/Users/juanpirossi/Documents/personal-projects/metegolBotTelegram/src/utils.py", line 30, in func_wrapper
    func(*args, **kwargs)
  File "/Users/juanpirossi/Documents/personal-projects/metegolBotTelegram/src/callbacks.py", line 28, in inline_button_callback
    _submit_confirm(bot, data, update.callback_query.message.chat_id)
  File "/Users/juanpirossi/Documents/personal-projects/metegolBotTelegram/src/games.py", line 205, in _submit_confirm
    weekly.submit(data)
  File "/Users/juanpirossi/Documents/personal-projects/metegolBotTelegram/src/weekly.py", line 25, in submit
    "code": player["code"],
TypeError: string indices must be integers
2019-09-11 12:32:46,014 - metegol - ERROR - string indices must be integers
Traceback (most recent call last):
  File "/Users/juanpirossi/Documents/personal-projects/metegolBotTelegram/src/utils.py", line 30, in func_wrapper
    func(*args, **kwargs)
  File "/Users/juanpirossi/Documents/personal-projects/metegolBotTelegram/src/callbacks.py", line 28, in inline_button_callback
    _submit_confirm(bot, data, update.callback_query.message.chat_id)
  File "/Users/juanpirossi/Documents/personal-projects/metegolBotTelegram/src/games.py", line 205, in _submit_confirm
    weekly.submit(data)
  File "/Users/juanpirossi/Documents/personal-projects/metegolBotTelegram/src/weekly.py", line 25, in submit
    "code": player["code"],
TypeError: string indices must be integers
2019-09-11 12:32:46,014 - metegol - ERROR - string indices must be integers
Traceback (most recent call last):
  File "/Users/juanpirossi/Documents/personal-projects/metegolBotTelegram/src/utils.py", line 30, in func_wrapper
    func(*args, **kwargs)
  File "/Users/juanpirossi/Documents/personal-projects/metegolBotTelegram/src/callbacks.py", line 28, in inline_button_callback
    _submit_confirm(bot, data, update.callback_query.message.chat_id)
  File "/Users/juanpirossi/Documents/personal-projects/metegolBotTelegram/src/games.py", line 205, in _submit_confirm
    weekly.submit(data)
  File "/Users/juanpirossi/Documents/personal-projects/metegolBotTelegram/src/weekly.py", line 25, in submit
    "code": player["code"],
TypeError: string indices must be integers
2019-09-11 12:32:46,014 - metegol - ERROR - string indices must be integers
Traceback (most recent call last):
  File "/Users/juanpirossi/Documents/personal-projects/metegolBotTelegram/src/utils.py", line 30, in func_wrapper
    func(*args, **kwargs)
  File "/Users/juanpirossi/Documents/personal-projects/metegolBotTelegram/src/callbacks.py", line 28, in inline_button_callback
    _submit_confirm(bot, data, update.callback_query.message.chat_id)
  File "/Users/juanpirossi/Documents/personal-projects/metegolBotTelegram/src/games.py", line 205, in _submit_confirm
    weekly.submit(data)
  File "/Users/juanpirossi/Documents/personal-projects/metegolBotTelegram/src/weekly.py", line 25, in submit
    "code": player["code"],
TypeError: string indices must be integers
2019-09-11 12:32:46,014 - metegol - ERROR - string indices must be integers
Traceback (most recent call last):
  File "/Users/juanpirossi/Documents/personal-projects/metegolBotTelegram/src/utils.py", line 30, in func_wrapper
    func(*args, **kwargs)
  File "/Users/juanpirossi/Documents/personal-projects/metegolBotTelegram/src/callbacks.py", line 28, in inline_button_callback
    _submit_confirm(bot, data, update.callback_query.message.chat_id)
  File "/Users/juanpirossi/Documents/personal-projects/metegolBotTelegram/src/games.py", line 205, in _submit_confirm
    weekly.submit(data)
  File "/Users/juanpirossi/Documents/personal-projects/metegolBotTelegram/src/weekly.py", line 25, in submit
    "code": player["code"],
TypeError: string indices must be integers
2019-09-11 12:32:46,014 - metegol - ERROR - string indices must be integers
Traceback (most recent call last):
  File "/Users/juanpirossi/Documents/personal-projects/metegolBotTelegram/src/utils.py", line 30, in func_wrapper
    func(*args, **kwargs)
  File "/Users/juanpirossi/Documents/personal-projects/metegolBotTelegram/src/callbacks.py", line 28, in inline_button_callback
    _submit_confirm(bot, data, update.callback_query.message.chat_id)
  File "/Users/juanpirossi/Documents/personal-projects/metegolBotTelegram/src/games.py", line 205, in _submit_confirm
    weekly.submit(data)
  File "/Users/juanpirossi/Documents/personal-projects/metegolBotTelegram/src/weekly.py", line 25, in submit
    "code": player["code"],
TypeError: string indices must be integers
2019-09-11 12:33:45,014 - metegol - ERROR - MISCONF Redis is configured to save RDB snapshots, but it is currently not able to persist on disk. Commands that may modify the data set are disabled, because this instance is configured to report errors during writes if RDB snapshotting fails (stop-writes-on-bgsave-error option). Please check the Redis logs for details about the RDB error.
Traceback (most recent call last):
  File "/Users/juanpirossi/Documents/personal-projects/metegolBotTelegram/src/utils.py", line 30, in func_wrapper
    func(*args, **kwargs)
  File "/Users/juanpirossi/Documents/personal-projects/metegolBotTelegram/src/games.py", line 28, in submit
    uid = redis_set(json.dumps(data))
  File "/Users/juanpirossi/Documents/personal-projects/metegolBotTelegram/src/utils.py", line 15, in redis_set
    r.set(uid, value, ex=300)
  File "/usr/local/lib/python3.7/site-packages/redis/client.py", line 1519, in set
    return self.execute_command('SET', *pieces)
  File "/usr/local/lib/python3.7/site-packages/redis/client.py", line 839, in execute_command
    return self.parse_response(conn, command_name, **options)
  File "/usr/local/lib/python3.7/site-packages/redis/client.py", line 853, in parse_response
    response = connection.read_response()
  File "/usr/local/lib/python3.7/site-packages/redis/connection.py", line 717, in read_response
    raise response
redis.exceptions.ResponseError: MISCONF Redis is configured to save RDB snapshots, but it is currently not able to persist on disk. Commands that may modify the data set are disabled, because this instance is configured to report errors during writes if RDB snapshotting fails (stop-writes-on-bgsave-error option). Please check the Redis logs for details about the RDB error.
2019-09-11 12:47:54,292 - metegol - ERROR - help() missing 1 required positional argument: 'args'
Traceback (most recent call last):
  File "/Users/juanpirossi/Documents/personal-projects/metegolBotTelegram/src/utils.py", line 30, in func_wrapper
    func(*args, **kwargs)
TypeError: help() missing 1 required positional argument: 'args'
2019-09-12 07:48:20,235 - metegol - ERROR - tuple index out of range
Traceback (most recent call last):
  File "/Users/juanpirossi/Documents/personal-projects/metegolBotTelegram/src/utils.py", line 29, in func_wrapper
    update = args[1]
IndexError: tuple index out of range
2019-09-12 07:50:26,806 - metegol - ERROR - tuple index out of range
Traceback (most recent call last):
  File "/Users/juanpirossi/Documents/personal-projects/metegolBotTelegram/src/utils.py", line 28, in func_wrapper
    bot = args[0]
IndexError: tuple index out of range
2019-09-12 07:50:38,768 - metegol - ERROR - tuple index out of range
Traceback (most recent call last):
  File "/Users/juanpirossi/Documents/personal-projects/metegolBotTelegram/src/utils.py", line 28, in func_wrapper
    bot = args[0]
IndexError: tuple index out of range
